<?xml version="1.0" ?>
<!-- =================================================================================== -->
<!-- |    This document was autogenerated by xacro from urdf\with_craw.xacro           | -->
<!-- |    EDITING THIS FILE BY HAND IS NOT RECOMMENDED                                 | -->
<!-- =================================================================================== -->
<robot xmlns:xacro="http://www.ros.org/wiki/xacro" name="with_craw">
  <material name="silver">
    <color rgba="0.700 0.700 0.700 1.000"/>
  </material>
  <transmission name="Revolute 21_tran">
    <type>transmission_interface/SimpleTransmission</type>
    <joint name="Revolute 21">
      <hardwareInterface>hardware_interface/EffortJointInterface</hardwareInterface>
    </joint>
    <actuator name="Revolute 21_actr">
      <hardwareInterface>hardware_interface/EffortJointInterface</hardwareInterface>
      <mechanicalReduction>1</mechanicalReduction>
    </actuator>
  </transmission>
  <transmission name="Revolute 22_tran">
    <type>transmission_interface/SimpleTransmission</type>
    <joint name="Revolute 22">
      <hardwareInterface>hardware_interface/EffortJointInterface</hardwareInterface>
    </joint>
    <actuator name="Revolute 22_actr">
      <hardwareInterface>hardware_interface/EffortJointInterface</hardwareInterface>
      <mechanicalReduction>1</mechanicalReduction>
    </actuator>
  </transmission>
  <transmission name="Revolute 34_tran">
    <type>transmission_interface/SimpleTransmission</type>
    <joint name="Revolute 34">
      <hardwareInterface>hardware_interface/EffortJointInterface</hardwareInterface>
    </joint>
    <actuator name="Revolute 34_actr">
      <hardwareInterface>hardware_interface/EffortJointInterface</hardwareInterface>
      <mechanicalReduction>1</mechanicalReduction>
    </actuator>
  </transmission>
  <transmission name="Revolute 40_tran">
    <type>transmission_interface/SimpleTransmission</type>
    <joint name="Revolute 40">
      <hardwareInterface>hardware_interface/EffortJointInterface</hardwareInterface>
    </joint>
    <actuator name="Revolute 40_actr">
      <hardwareInterface>hardware_interface/EffortJointInterface</hardwareInterface>
      <mechanicalReduction>1</mechanicalReduction>
    </actuator>
  </transmission>
  <transmission name="Revolute 41_tran">
    <type>transmission_interface/SimpleTransmission</type>
    <joint name="Revolute 41">
      <hardwareInterface>hardware_interface/EffortJointInterface</hardwareInterface>
    </joint>
    <actuator name="Revolute 41_actr">
      <hardwareInterface>hardware_interface/EffortJointInterface</hardwareInterface>
      <mechanicalReduction>1</mechanicalReduction>
    </actuator>
  </transmission>
  <transmission name="Revolute 42_tran">
    <type>transmission_interface/SimpleTransmission</type>
    <joint name="Revolute 42">
      <hardwareInterface>hardware_interface/EffortJointInterface</hardwareInterface>
    </joint>
    <actuator name="Revolute 42_actr">
      <hardwareInterface>hardware_interface/EffortJointInterface</hardwareInterface>
      <mechanicalReduction>1</mechanicalReduction>
    </actuator>
  </transmission>
  <transmission name="Slider 52_tran">
    <type>transmission_interface/SimpleTransmission</type>
    <joint name="Slider 52">
      <hardwareInterface>hardware_interface/EffortJointInterface</hardwareInterface>
    </joint>
    <actuator name="Slider 52_actr">
      <hardwareInterface>hardware_interface/EffortJointInterface</hardwareInterface>
      <mechanicalReduction>1</mechanicalReduction>
    </actuator>
  </transmission>
  <transmission name="Slider 53_tran">
    <type>transmission_interface/SimpleTransmission</type>
    <joint name="Slider 53">
      <hardwareInterface>hardware_interface/EffortJointInterface</hardwareInterface>
    </joint>
    <actuator name="Slider 53_actr">
      <hardwareInterface>hardware_interface/EffortJointInterface</hardwareInterface>
      <mechanicalReduction>1</mechanicalReduction>
    </actuator>
  </transmission>
  <gazebo>
    <plugin name="control" filename="libgazebo_ros_control.so"/>
  </gazebo>
  <gazebo reference="base_link">
    <material>Gazebo/Silver</material>
    <mu1>0.2</mu1>
    <mu2>0.2</mu2>
    <selfCollide>true</selfCollide>
    <gravity>true</gravity>
  </gazebo>
  <gazebo reference="joint252_1">
    <material>Gazebo/Silver</material>
    <mu1>0.2</mu1>
    <mu2>0.2</mu2>
    <selfCollide>true</selfCollide>
  </gazebo>
  <gazebo reference="25joint_v2_1">
    <material>Gazebo/Silver</material>
    <mu1>0.2</mu1>
    <mu2>0.2</mu2>
    <selfCollide>true</selfCollide>
  </gazebo>
  <gazebo reference="larm_1">
    <material>Gazebo/Silver</material>
    <mu1>0.2</mu1>
    <mu2>0.2</mu2>
    <selfCollide>true</selfCollide>
  </gazebo>
  <gazebo reference="25jointt_1">
    <material>Gazebo/Silver</material>
    <mu1>0.2</mu1>
    <mu2>0.2</mu2>
    <selfCollide>true</selfCollide>
  </gazebo>
  <gazebo reference="transv2_1">
    <material>Gazebo/Silver</material>
    <mu1>0.2</mu1>
    <mu2>0.2</mu2>
    <selfCollide>true</selfCollide>
  </gazebo>
  <gazebo reference="uarm_1">
    <material>Gazebo/Silver</material>
    <mu1>0.2</mu1>
    <mu2>0.2</mu2>
    <selfCollide>true</selfCollide>
  </gazebo>
  <gazebo reference="joint14_1">
    <material>Gazebo/Silver</material>
    <mu1>0.2</mu1>
    <mu2>0.2</mu2>
    <selfCollide>true</selfCollide>
  </gazebo>
  <gazebo reference="14joint44v2_1">
    <material>Gazebo/Silver</material>
    <mu1>0.2</mu1>
    <mu2>0.2</mu2>
    <selfCollide>true</selfCollide>
  </gazebo>
  <gazebo reference="joint143_1">
    <material>Gazebo/Silver</material>
    <mu1>0.2</mu1>
    <mu2>0.2</mu2>
    <selfCollide>true</selfCollide>
  </gazebo>
  <gazebo reference="flange_1">
    <material>Gazebo/Silver</material>
    <mu1>0.2</mu1>
    <mu2>0.2</mu2>
    <selfCollide>true</selfCollide>
  </gazebo>
  <gazebo reference="board_1">
    <material>Gazebo/Silver</material>
    <mu1>0.2</mu1>
    <mu2>0.2</mu2>
    <selfCollide>true</selfCollide>
  </gazebo>
  <gazebo reference="craw_1">
    <material>Gazebo/Silver</material>
    <mu1>0.2</mu1>
    <mu2>0.2</mu2>
    <selfCollide>true</selfCollide>
  </gazebo>
  <gazebo reference="cralwer_deap_1">
    <material>Gazebo/Silver</material>
    <mu1>0.2</mu1>
    <mu2>0.2</mu2>
    <selfCollide>true</selfCollide>
  </gazebo>
  <gazebo reference="cralwer_deap2_1">
    <material>Gazebo/Silver</material>
    <mu1>0.2</mu1>
    <mu2>0.2</mu2>
    <selfCollide>true</selfCollide>
  </gazebo>
  <link name="base_link">
    <inertial>
      <origin xyz="0.001848507400348535 0.00533236671337289 0.032315931711898914" rpy="0 0 0"/>
      <mass value="7.803232490794544"/>
      <inertia ixx="0.012989" iyy="0.01227" izz="0.018229" ixy="0.0" iyz="-1.6e-05" ixz="0.0"/>
    </inertial>
    <visual>
      <origin xyz="0 0 0" rpy="0 0 0"/>
      <geometry>
        <mesh filename="package://robot_description/meshes/base_link.stl" scale="0.001 0.001 0.001"/>
      </geometry>
      <material name="silver"/>
    </visual>
    <collision>
      <origin xyz="0 0 0" rpy="0 0 0"/>
      <geometry>
        <mesh filename="package://robot_description/meshes/base_link.stl" scale="0.001 0.001 0.001"/>
      </geometry>
    </collision>
  </link>
  <link name="joint252_1">
    <inertial>
      <origin xyz="-4.732017259291132e-07 -0.006406461035902656 0.07775349829951284" rpy="0 0 0"/>
      <mass value="15.540708623156794"/>
      <inertia ixx="0.045424" iyy="0.041918" izz="0.033427" ixy="0.0" iyz="-0.000116" ixz="0.0"/>
    </inertial>
    <visual>
      <origin xyz="-0.001849 -0.003782 -0.07" rpy="0 0 0"/>
      <geometry>
        <mesh filename="package://robot_description/meshes/joint252_1.stl" scale="0.001 0.001 0.001"/>
      </geometry>
      <material name="silver"/>
    </visual>
    <collision>
      <origin xyz="-0.001849 -0.003782 -0.07" rpy="0 0 0"/>
      <geometry>
        <mesh filename="package://robot_description/meshes/joint252_1.stl" scale="0.001 0.001 0.001"/>
      </geometry>
    </collision>
  </link>
  <link name="25joint_v2_1">
    <inertial>
      <origin xyz="-4.732017259206564e-07 -0.06359295040332738 -0.0012522954908724127" rpy="0 0 0"/>
      <mass value="15.540708623156803"/>
      <inertia ixx="0.045424" iyy="0.041918" izz="0.033427" ixy="-0.0" iyz="-0.000116" ixz="-0.0"/>
    </inertial>
    <visual>
      <origin xyz="-0.001849 0.066217 -0.146501" rpy="0 0 0"/>
      <geometry>
        <mesh filename="package://robot_description/meshes/25joint_v2_1.stl" scale="0.001 0.001 0.001"/>
      </geometry>
      <material name="silver"/>
    </visual>
    <collision>
      <origin xyz="-0.001849 0.066217 -0.146501" rpy="0 0 0"/>
      <geometry>
        <mesh filename="package://robot_description/meshes/25joint_v2_1.stl" scale="0.001 0.001 0.001"/>
      </geometry>
    </collision>
  </link>
  <link name="larm_1">
    <inertial>
      <origin xyz="-0.001849 0.137217 -0.213002" rpy="0 0 0"/>
      <mass value="0.0"/>
      <inertia ixx="0.0" iyy="0.0" izz="0.0" ixy="0.0" iyz="0.0" ixz="0.0"/>
    </inertial>
    <visual>
      <origin xyz="-0.001849 0.137217 -0.213002" rpy="0 0 0"/>
      <geometry>
        <mesh filename="package://robot_description/meshes/larm_1.stl" scale="0.001 0.001 0.001"/>
      </geometry>
      <material name="silver"/>
    </visual>
    <collision>
      <origin xyz="-0.001849 0.137217 -0.213002" rpy="0 0 0"/>
      <geometry>
        <mesh filename="package://robot_description/meshes/larm_1.stl" scale="0.001 0.001 0.001"/>
      </geometry>
    </collision>
  </link>
  <link name="25jointt_1">
    <inertial>
      <origin xyz="-4.920894866981568e-07 0.007407049596672405 0.06775367435817886" rpy="0 0 0"/>
      <mass value="15.540708623156789"/>
      <inertia ixx="0.045424" iyy="0.041918" izz="0.033427" ixy="0.0" iyz="0.000116" ixz="-0.0"/>
    </inertial>
    <visual>
      <origin xyz="-0.001849 0.137217 -0.481087" rpy="0 0 0"/>
      <geometry>
        <mesh filename="package://robot_description/meshes/25jointt_1.stl" scale="0.001 0.001 0.001"/>
      </geometry>
      <material name="silver"/>
    </visual>
    <collision>
      <origin xyz="-0.001849 0.137217 -0.481087" rpy="0 0 0"/>
      <geometry>
        <mesh filename="package://robot_description/meshes/25jointt_1.stl" scale="0.001 0.001 0.001"/>
      </geometry>
    </collision>
  </link>
  <link name="transv2_1">
    <inertial>
      <origin xyz="-4.841560476990994e-07 0.048347864687305626 0.0023735953077494987" rpy="0 0 0"/>
      <mass value="9.761584230310485"/>
      <inertia ixx="0.01826" iyy="0.019423" izz="0.017278" ixy="0.0" iyz="8.1e-05" ixz="0.0"/>
    </inertial>
    <visual>
      <origin xyz="-0.001849 0.066217 -0.547588" rpy="0 0 0"/>
      <geometry>
        <mesh filename="package://robot_description/meshes/transv2_1.stl" scale="0.001 0.001 0.001"/>
      </geometry>
      <material name="silver"/>
    </visual>
    <collision>
      <origin xyz="-0.001849 0.066217 -0.547588" rpy="0 0 0"/>
      <geometry>
        <mesh filename="package://robot_description/meshes/transv2_1.stl" scale="0.001 0.001 0.001"/>
      </geometry>
    </collision>
  </link>
  <link name="uarm_1">
    <inertial>
      <origin xyz="-0.001849 0.021217 -0.612688" rpy="0 0 0"/>
      <mass value="0.0"/>
      <inertia ixx="0.0" iyy="0.0" izz="0.0" ixy="0.0" iyz="0.0" ixz="0.0"/>
    </inertial>
    <visual>
      <origin xyz="-0.001849 0.021217 -0.612688" rpy="0 0 0"/>
      <geometry>
        <mesh filename="package://robot_description/meshes/uarm_1.stl" scale="0.001 0.001 0.001"/>
      </geometry>
      <material name="silver"/>
    </visual>
    <collision>
      <origin xyz="-0.001849 0.021217 -0.612688" rpy="0 0 0"/>
      <geometry>
        <mesh filename="package://robot_description/meshes/uarm_1.stl" scale="0.001 0.001 0.001"/>
      </geometry>
    </collision>
  </link>
  <link name="joint14_1">
    <inertial>
      <origin xyz="-4.756562241251677e-07 0.0013161557636816243 0.044490051559664234" rpy="0 0 0"/>
      <mass value="6.462489586316139"/>
      <inertia ixx="0.012155" iyy="0.006667" izz="0.011497" ixy="0.0" iyz="-4.7e-05" ixz="0.0"/>
    </inertial>
    <visual>
      <origin xyz="-0.001849 0.021217 -0.839688" rpy="0 0 0"/>
      <geometry>
        <mesh filename="package://robot_description/meshes/joint14_1.stl" scale="0.001 0.001 0.001"/>
      </geometry>
      <material name="silver"/>
    </visual>
    <collision>
      <origin xyz="-0.001849 0.021217 -0.839688" rpy="0 0 0"/>
      <geometry>
        <mesh filename="package://robot_description/meshes/joint14_1.stl" scale="0.001 0.001 0.001"/>
      </geometry>
    </collision>
  </link>
  <link name="14joint44v2_1">
    <inertial>
      <origin xyz="-4.89634955042539e-07 -0.04448997981623426 -0.0013160840202266488" rpy="0 0 0"/>
      <mass value="6.462489586316137"/>
      <inertia ixx="0.012155" iyy="0.011497" izz="0.006667" ixy="0.0" iyz="-4.7e-05" ixz="0.0"/>
    </inertial>
    <visual>
      <origin xyz="-0.001849 0.079217 -0.888688" rpy="0 0 0"/>
      <geometry>
        <mesh filename="package://robot_description/meshes/14joint44v2_1.stl" scale="0.001 0.001 0.001"/>
      </geometry>
      <material name="silver"/>
    </visual>
    <collision>
      <origin xyz="-0.001849 0.079217 -0.888688" rpy="0 0 0"/>
      <geometry>
        <mesh filename="package://robot_description/meshes/14joint44v2_1.stl" scale="0.001 0.001 0.001"/>
      </geometry>
    </collision>
  </link>
  <link name="joint143_1">
    <inertial>
      <origin xyz="-4.7565622413882867e-07 0.0013161557637089705 0.04449005155969088" rpy="0 0 0"/>
      <mass value="6.462489586316132"/>
      <inertia ixx="0.012155" iyy="0.006667" izz="0.011497" ixy="0.0" iyz="-4.7e-05" ixz="0.0"/>
    </inertial>
    <visual>
      <origin xyz="-0.001849 0.128217 -0.946688" rpy="0 0 0"/>
      <geometry>
        <mesh filename="package://robot_description/meshes/joint143_1.stl" scale="0.001 0.001 0.001"/>
      </geometry>
      <material name="silver"/>
    </visual>
    <collision>
      <origin xyz="-0.001849 0.128217 -0.946688" rpy="0 0 0"/>
      <geometry>
        <mesh filename="package://robot_description/meshes/joint143_1.stl" scale="0.001 0.001 0.001"/>
      </geometry>
    </collision>
  </link>
  <link name="flange_1">
    <inertial>
      <origin xyz="-4.826455904198817e-07 -0.01210702329269897 -2.6382789386936167e-05" rpy="0 0 0"/>
      <mass value="1.2487889322710095"/>
      <inertia ixx="0.000662" iyy="0.001091" izz="0.000662" ixy="-0.0" iyz="-1e-06" ixz="0.0"/>
    </inertial>
    <visual>
      <origin xyz="-0.001849 0.186217 -0.995688" rpy="0 0 0"/>
      <geometry>
        <mesh filename="package://robot_description/meshes/flange_1.stl" scale="0.001 0.001 0.001"/>
      </geometry>
      <material name="silver"/>
    </visual>
    <collision>
      <origin xyz="-0.001849 0.186217 -0.995688" rpy="0 0 0"/>
      <geometry>
        <mesh filename="package://robot_description/meshes/flange_1.stl" scale="0.001 0.001 0.001"/>
      </geometry>
    </collision>
  </link>
  <link name="board_1">
    <inertial>
      <origin xyz="-4.826455891051781e-07 -0.002505172502402314 0.02755397289155359" rpy="0 0 0"/>
      <mass value="0.3723965227028356"/>
      <inertia ixx="0.000357" iyy="0.000605" izz="0.00025" ixy="0.0" iyz="0.0" ixz="-0.0"/>
    </inertial>
    <visual>
      <origin xyz="-0.001849 0.217717 -0.995688" rpy="0 0 0"/>
      <geometry>
        <mesh filename="package://robot_description/meshes/board_1.stl" scale="0.001 0.001 0.001"/>
      </geometry>
      <material name="silver"/>
    </visual>
    <collision>
      <origin xyz="-0.001849 0.217717 -0.995688" rpy="0 0 0"/>
      <geometry>
        <mesh filename="package://robot_description/meshes/board_1.stl" scale="0.001 0.001 0.001"/>
      </geometry>
    </collision>
  </link>
  <link name="craw_1">
    <inertial>
      <origin xyz="0.034087163819984216 -0.028003110619122862 -0.011999722536958357" rpy="0 0 0"/>
      <mass value="2.052982330856382"/>
      <inertia ixx="0.000782" iyy="0.003426" izz="0.003843" ixy="-8.9e-05" iyz="0.0" ixz="0.0"/>
    </inertial>
    <visual>
      <origin xyz="0.032651 0.223717 -1.055188" rpy="0 0 0"/>
      <geometry>
        <mesh filename="package://robot_description/meshes/craw_1.stl" scale="0.001 0.001 0.001"/>
      </geometry>
      <material name="silver"/>
    </visual>
    <collision>
      <origin xyz="0.032651 0.223717 -1.055188" rpy="0 0 0"/>
      <geometry>
        <mesh filename="package://robot_description/meshes/craw_1.stl" scale="0.001 0.001 0.001"/>
      </geometry>
    </collision>
  </link>
  <link name="cralwer_deap_1">
    <inertial>
      <origin xyz="-0.03526468017645347 -0.033147119299760386 -0.008749722536942839" rpy="0 0 0"/>
      <mass value="0.28613249999999474"/>
      <inertia ixx="0.000341" iyy="0.00027" izz="0.00046" ixy="-0.000146" iyz="0.0" ixz="0.0"/>
    </inertial>
    <visual>
      <origin xyz="0.023651 0.277717 -1.051938" rpy="0 0 0"/>
      <geometry>
        <mesh filename="package://robot_description/meshes/cralwer_deap_1.stl" scale="0.001 0.001 0.001"/>
      </geometry>
      <material name="silver"/>
    </visual>
    <collision>
      <origin xyz="0.023651 0.277717 -1.051938" rpy="0 0 0"/>
      <geometry>
        <mesh filename="package://robot_description/meshes/cralwer_deap_1.stl" scale="0.001 0.001 0.001"/>
      </geometry>
    </collision>
  </link>
  <link name="cralwer_deap2_1">
    <inertial>
      <origin xyz="0.03526371488527427 -0.03314711929976033 -0.008749722536943949" rpy="0 0 0"/>
      <mass value="0.2861324999999951"/>
      <inertia ixx="0.000341" iyy="0.00027" izz="0.00046" ixy="0.000146" iyz="0.0" ixz="-0.0"/>
    </inertial>
    <visual>
      <origin xyz="-0.030349 0.277717 -1.051938" rpy="0 0 0"/>
      <geometry>
        <mesh filename="package://robot_description/meshes/cralwer_deap2_1.stl" scale="0.001 0.001 0.001"/>
      </geometry>
      <material name="silver"/>
    </visual>
    <collision>
      <origin xyz="-0.030349 0.277717 -1.051938" rpy="0 0 0"/>
      <geometry>
        <mesh filename="package://robot_description/meshes/cralwer_deap2_1.stl" scale="0.001 0.001 0.001"/>
      </geometry>
    </collision>
  </link>

  <link name="virtual_tip_link">
    <inertial>
      <mass value="0.00001"/>
      <origin xyz="0 -0.08 0"/>
      <inertia ixx="1e-6" iyy="1e-6" izz="1e-6" ixy="0" ixz="0" iyz="0"/>
    </inertial>
  </link>
  <joint name="Revolute 21" type="continuous">
    <origin xyz="0.001849 0.003782 0.07" rpy="0 0 0"/>
    <parent link="base_link"/>
    <child link="joint252_1"/>
    <axis xyz="0.0 0.0 1.0"/>
  </joint>
  <joint name="Revolute_22" type="revolute">
    <origin xyz="0.0 -0.069999 0.076501" rpy="0 0 0"/>
    <parent link="joint252_1"/>
    <child link="25joint_v2_1"/>
    <axis xyz="0.0 -1.0 0.0"/>
    <limit lower="-1.47" upper="1.47" effort="10" velocity="1.0"/>
    <!--limit lower="-0.175" upper="0.175" effort="10" velocity="1.0"/-->
  </joint>

  <joint name="Rigid 30" type="fixed">
    <origin xyz="0.0 -0.071 0.066501" rpy="0 0 0"/>
    <parent link="25joint_v2_1"/>
    <child link="larm_1"/>
  </joint>
  <joint name="Rigid 32" type="fixed">
    <origin xyz="0.0 0.0 0.268085" rpy="0 0 0"/>
    <parent link="larm_1"/>
    <child link="25jointt_1"/>
  </joint>
  <joint name="Revolute 34" type="continuous">
    <origin xyz="0.0 0.071 0.066501" rpy="0 0 0"/>
    <parent link="25jointt_1"/>
    <child link="transv2_1"/>
    <axis xyz="0.0 -1.0 0.0"/>
  </joint>
  <joint name="Rigid 35" type="fixed">
    <origin xyz="0.0 0.045 0.0651" rpy="0 0 0"/>
    <parent link="transv2_1"/>
    <child link="uarm_1"/>
  </joint>
  <joint name="Rigid 37" type="fixed">
    <origin xyz="0.0 0.0 0.227" rpy="0 0 0"/>
    <parent link="uarm_1"/>
    <child link="joint14_1"/>
  </joint>
  <joint name="Revolute 40" type="continuous">
    <origin xyz="0.0 -0.058 0.049" rpy="0 0 0"/>
    <parent link="joint14_1"/>
    <child link="14joint44v2_1"/>
    <axis xyz="0.0 -1.0 -0.0"/>
  </joint>
  <joint name="Revolute 41" type="continuous">
    <origin xyz="0.0 -0.049 0.058" rpy="0 0 0"/>
    <parent link="14joint44v2_1"/>
    <child link="joint143_1"/>
    <axis xyz="0.0 -0.0 1.0"/>
  </joint>
  <joint name="Revolute 42" type="continuous">
    <origin xyz="0.0 -0.058 0.049" rpy="0 0 0"/>
    <parent link="joint143_1"/>
    <child link="flange_1"/>
    <axis xyz="0.0 -1.0 -0.0"/>
  </joint>
  <joint name="Rigid 43" type="fixed">
    <origin xyz="0.0 -0.0315 0.0" rpy="0 0 0"/>
    <parent link="flange_1"/>
    <child link="board_1"/>
  </joint>
  <joint name="Rigid 44" type="fixed">
    <origin xyz="-0.0345 -0.006 0.0595" rpy="0 0 0"/>
    <parent link="board_1"/>
    <child link="craw_1"/>
  </joint>
  <joint name="Slider 52" type="prismatic">
    <origin xyz="0.009 -0.054 -0.00325" rpy="0 0 0"/>
    <parent link="craw_1"/>
    <child link="cralwer_deap_1"/>
    <axis xyz="1.0 -0.0 -0.0"/>
    <limit upper="0.01" lower="-0.01" effort="100" velocity="100"/>
  </joint>
  <joint name="Slider 53" type="prismatic">
    <origin xyz="0.063 -0.054 -0.00325" rpy="0 0 0"/>
    <parent link="craw_1"/>
    <child link="cralwer_deap2_1"/>
    <axis xyz="1.0 -0.0 -0.0"/>
    <limit upper="0.01" lower="-0.01" effort="100" velocity="100"/>
  </joint>
    <joint name="virtual_tip_joint" type="revolute">
    <parent link="craw_1"/> <!-- 改成共用父連結 -->
    <child link="virtual_tip_link"/>
    <origin xyz=" 0.036 -0.054 -0.00325" rpy="3.14 3.14 1.57"/> <!-- 位置依你要掛在中間點的 offset 調整 -->
    <axis xyz="1 0 0"/>
    <limit lower="0" upper="0" effort="0" velocity="0"/>
  </joint>
</robot>